Workbook

Sheet variable definitions Stephen
A1: variable | B1: description | C1: air_travel | D1: air_travel_d | E1: air_travel_i | F1: public | G1: pub_ex_season | H1: cycling | I1: other | J1: taxis | K1: vcle_prchse | L1: vcle_run | M1: vcle_total | N1: surface | O1: domestic | P1: all
A2: b216 | B2: Bus + tube and/or rail season | C2: 0 | D2: 0 | E2: 0 | F2: 1 | G2: 0 | H2: 0 | I2: 0 | J2: 0 | K2: 0 | L2: 0 | M2: =IF(K2=0,L2,K2) -> 0 | N2: 1 | O2: 1 | P2: 1
A3: b217 | B3: Season ticket - bus / coach - total net amount | C3: 0 | D3: 0 | E3: 0 | F3: 1 | G3: 0 | H3: 0 | I3: 0 | J3: 0 | K3: 0 | L3: 0 | M3: =IF(K3=0,L3,K3) -> 0 | N3: 1 | O3: 1 | P3: 1
A4: b218 | B4: Season ticket - rail / tube - total net amount | C4: 0 | D4: 0 | E4: 0 | F4: 1 | G4: 0 | H4: 0 | I4: 0 | J4: 0 | K4: 0 | L4: 0 | M4: =IF(K4=0,L4,K4) -> 0 | N4: 1 | O4: 1 | P4: 1
A5: b219 | B5: Water travel season ticket | C5: 0 | D5: 0 | E5: 0 | F5: 1 | G5: 0 | H5: 0 | I5: 0 | J5: 0 | K5: 0 | L5: 0 | M5: =IF(K5=0,L5,K5) -> 0 | N5: 1 | O5: 1 | P5: 1
A6: b244 | B6: Vehicle - cost of new car | van outright | C6: 0 | D6: 0 | E6: 0 | F6: 0 | G6: 0 | H6: 0 | I6: 0 | J6: 0 | K6: 1 | L6: 0 | M6: =IF(K6=0,L6,K6) -> 1 | N6: 1 | O6: 1 | P6: 1
A7: b2441 | B7: Vehicle - cost of new motor caravan outright | C7: 0 | D7: 0 | E7: 0 | F7: 0 | G7: 0 | H7: 0 | I7: 0 | J7: 0 | K7: 1 | L7: 0 | M7: =IF(K7=0,L7,K7) -> 1 | N7: 1 | O7: 1 | P7: 1
A8: b245 | B8: Vehicle - cost of 2nd hand car | van outright | C8: 0 | D8: 0 | E8: 0 | F8: 0 | G8: 0 | H8: 0 | I8: 0 | J8: 0 | K8: 1 | L8: 0 | M8: =IF(K8=0,L8,K8) -> 1 | N8: 1 | O8: 1 | P8: 1
A9: b2451 | B9: Vehicle cost of 2nd hand motor caravan outright | C9: 0 | D9: 0 | E9: 0 | F9: 0 | G9: 0 | H9: 0 | I9: 0 | J9: 0 | K9: 1 | L9: 0 | M9: =IF(K9=0,L9,K9) -> 1 | N9: 1 | O9: 1 | P9: 1
A10: b247 | B10: Vehicle - cost of motorcycles outright | C10: 0 | D10: 0 | E10: 0 | F10: 0 | G10: 0 | H10: 0 | I10: 0 | J10: 0 | K10: 1 | L10: 0 | M10: =IF(K10=0,L10,K10) -> 1 | N10: 1 | O10: 1 | P10: 1
A11: b248 | B11: Car leasing - expenditure on | C11: 0 | D11: 0 | E11: 0 | F11: 0 | G11: 0 | H11: 0 | I11: 0 | J11: 0 | K11: 1 | L11: 0 | M11: =IF(K11=0,L11,K11) -> 1 | N11: 1 | O11: 1 | P11: 1
A12: b249 | B12: Car or van - servicing: amount paid | C12: 0 | D12: 0 | E12: 0 | F12: 0 | G12: 0 | H12: 0 | I12: 0 | J12: 0 | K12: 0 | L12: 1 | M12: =IF(K12=0,L12,K12) -> 1 | N12: 1 | O12: 1 | P12: 1
A13: b250 | B13: Car or van - other works, repairs: amount paid | C13: 0 | D13: 0 | E13: 0 | F13: 0 | G13: 0 | H13: 0 | I13: 0 | J13: 0 | K13: 0 | L13: 1 | M13: =IF(K13=0,L13,K13) -> 1 | N13: 1 | O13: 1 | P13: 1
... A53: c92114t | B53: Purchase of motor caravan (new) - loan/HP | C53: 0 | D53: 0 | E53: 0 | F53: 0 | G53: 0 | H53: 0 | I53: 0 | J53: 0 | K53: 1 | L53: 0 | M53: =IF(K53=0,L53,K53) -> 1 | N53: 1 | O53: 1 | P53: 1

Sheet variable labels Stephen
A1: index | B1: variable | C1: label | D1: char_check
A2: 1 | B2: {=INDEX('variable definitions Stephen'!$1:$1,2+A2)} -> air_travel | C2: Air travel | D2: =LEN(B2) -> 10
A3: =A2+1 -> 2 | B3: {=INDEX('variable definitions Stephen'!$1:$1,2+A3)} -> air_travel_d | C3: Domestic air travel | D3: =LEN(B3) -> 12
A4: =A3+1 -> 3 | B4: {=INDEX('variable definitions Stephen'!$1:$1,2+A4)} -> air_travel_i | C4: International air travel | D4: =LEN(B4) -> 12
A5: =A4+1 -> 4 | B5: {=INDEX('variable definitions Stephen'!$1:$1,2+A5)} -> public | C5: Public transport | D5: =LEN(B5) -> 6
A6: =A5+1 -> 5 | B6: {=INDEX('variable definitions Stephen'!$1:$1,2+A6)} -> pub_ex_season | C6: Public excl season tickets | D6: =LEN(B6) -> 13
A7: =A6+1 -> 6 | B7: {=INDEX('variable definitions Stephen'!$1:$1,2+A7)} -> cycling | C7: Cycling | D7: =LEN(B7) -> 7
A8: =A7+1 -> 7 | B8: {=INDEX('variable definitions Stephen'!$1:$1,2+A8)} -> other | C8: Other (school, personal, animal, hire) | D8: =LEN(B8) -> 5
A9: =A8+1 -> 8 | B9: {=INDEX('variable definitions Stephen'!$1:$1,2+A9)} -> taxis | C9: Taxis and minicabs | D9: =LEN(B9) -> 5
A10: =A9+1 -> 9 | B10: {=INDEX('variable definitions Stephen'!$1:$1,2+A10)} -> vcle_prchse | C10: Purchase or leasing of vehicles | D10: =LEN(B10) -> 11
A11: =A10+1 -> 10 | B11: {=INDEX('variable definitions Stephen'!$1:$1,2+A11)} -> vcle_run | C11: Operation of private vehicles | D11: =LEN(B11) -> 8
A12: =A11+1 -> 11 | B12: {=INDEX('variable definitions Stephen'!$1:$1,2+A12)} -> vcle_total | C12: Total cost of private vehicles | D12: =LEN(B12) -> 10
A13: =A12+1 -> 12 | B13: {=INDEX('variable definitions Stephen'!$1:$1,2+A13)} -> surface | C13: Surface transport | D13: =LEN(B13) -> 7
A14: =A13+1 -> 13 | B14: {=INDEX('variable definitions Stephen'!$1:$1,2+A14)} -> domestic | C14: Domestic transport | D14: =LEN(B14) -> 8
A15: =A14+1 -> 14 | B15: {=INDEX('variable definitions Stephen'!$1:$1,2+A15)} -> all | C15: All transport | D15: =LEN(B15) -> 3

Sheet variable definitions Maya
A1: variable | B1: description | C1: bus_and_coach | D1: bicylces | E1: school | F1: taxis | G1: fuel | H1: servicing | I1: garage | J1: fees | K1: insurance
A2: b216 | B2: Bus + tube and/or rail season | C2: 0 | D2: 0 | E2: 0 | F2: 0 | G2: 0 | H2: 0 | I2: 0 | J2: 0 | K2: 0
A3: b217 | B3: Season ticket - bus / coach - total net amount | C3: 1 | D3: 0 | E3: 0 | F3: 0 | G3: 0 | H3: 0 | I3: 0 | J3: 0 | K3: 0
A4: b218 | B4: Season ticket - rail / tube - total net amount | C4: 0 | D4: 0 | E4: 0 | F4: 0 | G4: 0 | H4: 0 | I4: 0 | J4: 0 | K4: 0
A5: b219 | B5: Water travel season ticket | C5: 0 | D5: 0 | E5: 0 | F5: 0 | G5: 0 | H5: 0 | I5: 0 | J5: 0 | K5: 0
A6: b244 | B6: Vehicle - cost of new car | van outright | C6: 0 | D6: 0 | E6: 0 | F6: 0 | G6: 0 | H6: 0 | I6: 0 | J6: 0 | K6: 0
A7: b2441 | B7: Vehicle - cost of new motor caravan outright | C7: 0 | D7: 0 | E7: 0 | F7: 0 | G7: 0 | H7: 0 | I7: 0 | J7: 0 | K7: 0
A8: b245 | B8: Vehicle - cost of 2nd hand car | van outright | C8: 0 | D8: 0 | E8: 0 | F8: 0 | G8: 0 | H8: 0 | I8: 0 | J8: 0 | K8: 0
A9: b2451 | B9: Vehicle cost of 2nd hand motor caravan outright | C9: 0 | D9: 0 | E9: 0 | F9: 0 | G9: 0 | H9: 0 | I9: 0 | J9: 0 | K9: 0
A10: b247 | B10: Vehicle - cost of motorcycles outright | C10: 0 | D10: 0 | E10: 0 | F10: 0 | G10: 0 | H10: 0 | I10: 0 | J10: 0 | K10: 0
A11: b248 | B11: Car leasing - expenditure on | C11: 0 | D11: 0 | E11: 0 | F11: 0 | G11: 0 | H11: 0 | I11: 0 | J11: 0 | K11: 0
A12: b249 | B12: Car or van - servicing: amount paid | C12: 0 | D12: 0 | E12: 0 | F12: 0 | G12: 0 | H12: 1 | I12: 0 | J12: 0 | K12: 0
A13: b250 | B13: Car or van - other works, repairs: amount paid | C13: 0 | D13: 0 | E13: 0 | F13: 0 | G13: 0 | H13: 1 | I13: 0 | J13: 0 | K13: 0
... A53: c92114t | B53: Purchase of motor caravan (new) - loan/HP | C53: 0 | D53: 0 | E53: 0 | F53: 0 | G53: 0 | H53: 0 | I53: 0 | J53: 0 | K53: 0

Sheet variable labels Maya
A1: index | B1: variable | C1: label
A2: 1 | B2: {=INDEX('variable definitions Maya'!$1:$1,2+A2)} -> bus_and_coach | C2: Bus and coach
A3: =A2+1 -> 2 | B3: {=INDEX('variable definitions Maya'!$1:$1,2+A3)} -> bicylces | C3: Cycline
A4: =A3+1 -> 3 | B4: {=INDEX('variable definitions Maya'!$1:$1,2+A4)} -> school | C4: School travel
A5: =A4+1 -> 4 | B5: {=INDEX('variable definitions Maya'!$1:$1,2+A5)} -> taxis | C5: Taxis
A6: =A5+1 -> 5 | B6: {=INDEX('variable definitions Maya'!$1:$1,2+A6)} -> fuel | C6: Fuel
A7: =A6+1 -> 6 | B7: {=INDEX('variable definitions Maya'!$1:$1,2+A7)} -> servicing | C7: Servicing and maintenance
A8: =A7+1 -> 7 | B8: {=INDEX('variable definitions Maya'!$1:$1,2+A8)} -> garage | C8: Garage rent, MOT etc
A9: =A8+1 -> 8 | B9: {=INDEX('variable definitions Maya'!$1:$1,2+A9)} -> fees | C9: Fees and tolls
A10: =A9+1 -> 9 | B10: {=INDEX('variable definitions Maya'!$1:$1,2+A10)} -> insurance | C10: Vehicle insurance (amount paid last year)

Sheet variable definitions Stephen2
A1: variable | B1: description | C1: surface | D1: vcle_total | E1: vcle_prchse | F1: vcle_run | G1: public | H1: cycling | I1: taxis | J1: pub_multi | K1: pub_bus_coach | L1: pub_rail_tube | M1: pub_water | N1: motor1 | O1: motor2 | P1: motor3 | Q1: motor4 | R1: motor5 | S1: motor6 | T1: motor7 | U1: fuel | V1: insurance | W1: maintenance | X1: motor_other
A2: b216 | B2: Bus + tube and/or rail season | C2: 1 | D2: 0 | E2: 0 | F2: 0 | G2: 1 | H2: 0 | I2: 0 | J2: 1 | K2: 0 | L2: 0 | M2: 0 | N2: 0 | O2: 0 | P2: 0 | Q2: 0 | R2: 0 | S2: 0 | T2: 0 | U2: 0 | V2: 0 | W2: 0 | X2: 0
A3: b217 | B3: Season ticket - bus / coach - total net amount | C3: 1 | D3: 0 | E3: 0 | F3: 0 | G3: 1 | H3: 0 | I3: 0 | J3: 0 | K3: 1 | L3: 0 | M3: 0 | N3: 0 | O3: 0 | P3: 0 | Q3: 0 | R3: 0 | S3: 0 | T3: 0 | U3: 0 | V3: 0 | W3: 0 | X3: 0
A4: b218 | B4: Season ticket - rail / tube - total net amount | C4: 1 | D4: 0 | E4: 0 | F4: 0 | G4: 1 | H4: 0 | I4: 0 | J4: 0 | K4: 0 | L4: 1 | M4: 0 | N4: 0 | O4: 0 | P4: 0 | Q4: 0 | R4: 0 | S4: 0 | T4: 0 | U4: 0 | V4: 0 | W4: 0 | X4: 0
A5: b219 | B5: Water travel season ticket | C5: 1 | D5: 0 | E5: 0 | F5: 0 | G5: 1 | H5: 0 | I5: 0 | J5: 0 | K5: 0 | L5: 0 | M5: 1 | N5: 0 | O5: 0 | P5: 0 | Q5: 0 | R5: 0 | S5: 0 | T5: 0 | U5: 0 | V5: 0 | W5: 0 | X5: 0
A6: b244 | B6: Vehicle - cost of new car | van outright | C6: 1 | D6: 1 | E6: 1 | F6: 0 | G6: 0 | H6: 0 | I6: 0 | J6: 0 | K6: 0 | L6: 0 | M6: 0 | N6: 1 | O6: 0 | P6: 0 | Q6: 0 | R6: 0 | S6: 0 | T6: 0 | U6: 0 | V6: 0 | W6: 0 | X6: 0
A7: b2441 | B7: Vehicle - cost of new motor caravan outright | C7: 1 | D7: 1 | E7: 1 | F7: 0 | G7: 0 | H7: 0 | I7: 0 | J7: 0 | K7: 0 | L7: 0 | M7: 0 | N7: 0 | O7: 0 | P7: 0 | Q7: 0 | R7: 0 | S7: 0 | T7: 0 | U7: 0 | V7: 0 | W7: 0 | X7: 0
A8: b245 | B8: Vehicle - cost of 2nd hand car | van outright | C8: 1 | D8: 1 | E8: 1 | F8: 0 | G8: 0 | H8: 0 | I8: 0 | J8: 0 | K8: 0 | L8: 0 | M8: 0 | N8: 0 | O8: 1 | P8: 0 | Q8: 0 | R8: 0 | S8: 0 | T8: 0 | U8: 0 | V8: 0 | W8: 0 | X8: 0
A9: b2451 | B9: Vehicle cost of 2nd hand motor caravan outright | C9: 1 | D9: 1 | E9: 1 | F9: 0 | G9: 0 | H9: 0 | I9: 0 | J9: 0 | K9: 0 | L9: 0 | M9: 0 | N9: 0 | O9: 0 | P9: 0 | Q9: 0 | R9: 0 | S9: 0 | T9: 0 | U9: 0 | V9: 0 | W9: 0 | X9: 0
A10: b247 | B10: Vehicle - cost of motorcycles outright | C10: 1 | D10: 1 | E10: 1 | F10: 0 | G10: 0 | H10: 0 | I10: 0 | J10: 0 | K10: 0 | L10: 0 | M10: 0 | N10: 0 | O10: 0 | P10: 1 | Q10: 0 | R10: 0 | S10: 0 | T10: 0 | U10: 0 | V10: 0 | W10: 0 | X10: 0
A11: b248 | B11: Car leasing - expenditure on | C11: 1 | D11: 1 | E11: 1 | F11: 0 | G11: 0 | H11: 0 | I11: 0 | J11: 0 | K11: 0 | L11: 0 | M11: 0 | N11: 0 | O11: 0 | P11: 0 | Q11: 0 | R11: 0 | S11: 0 | T11: 1 | U11: 0 | V11: 0 | W11: 0 | X11: 0
A12: b249 | B12: Car or van - servicing: amount paid | C12: 1 | D12: 1 | E12: 0 | F12: 1 | G12: 0 | H12: 0 | I12: 0 | J12: 0 | K12: 0 | L12: 0 | M12: 0 | N12: 0 | O12: 0 | P12: 0 | Q12: 0 | R12: 0 | S12: 0 | T12: 0 | U12: 0 | V12: 0 | W12: 1 | X12: 0
A13: b250 | B13: Car or van - other works, repairs: amount paid | C13: 1 | D13: 1 | E13: 0 | F13: 1 | G13: 0 | H13: 0 | I13: 0 | J13: 0 | K13: 0 | L13: 0 | M13: 0 | N13: 0 | O13: 0 | P13: 0 | Q13: 0 | R13: 0 | S13: 0 | T13: 0 | U13: 0 | V13: 0 | W13: 1 | X13: 0
... A53: c92114t | B53: Purchase of motor caravan (new) - loan/HP | C53: 1 | D53: 1 | E53: 1 | F53: 0 | G53: 0 | H53: 0 | I53: 0 | J53: 0 | K53: 0 | L53: 0 | M53: 0 | N53: 0 | O53: 0 | P53: 0 | Q53: 0 | R53: 0 | S53: 0 | T53: 0 | U53: 0 | V53: 0 | W53: 0 | X53: 0

Sheet variable labels Stephen2
A1: index | B1: variable | C1: label | D1: char_check
A2: 1 | B2: {=INDEX('variable definitions Stephen2'!$1:$1,2+A2)} -> surface | C2: Surface transport | D2: =LEN(B2) -> 7
A3: =A2+1 -> 2 | B3: {=INDEX('variable definitions Stephen2'!$1:$1,2+A3)} -> vcle_total | C3: Private vehicle (total) | D3: =LEN(B3) -> 10
A4: =A3+1 -> 3 | B4: {=INDEX('variable definitions Stephen2'!$1:$1,2+A4)} -> vcle_prchse | C4: Private vehicle (purchase) | D4: =LEN(B4) -> 11
A5: =A4+1 -> 4 | B5: {=INDEX('variable definitions Stephen2'!$1:$1,2+A5)} -> vcle_run | C5: Private vehicle (running) | D5: =LEN(B5) -> 8
A6: =A5+1 -> 5 | B6: {=INDEX('variable definitions Stephen2'!$1:$1,2+A6)} -> public | C6: Public transport | D6: =LEN(B6) -> 6
A7: =A6+1 -> 6 | B7: {=INDEX('variable definitions Stephen2'!$1:$1,2+A7)} -> cycling | C7: Cycling | D7: =LEN(B7) -> 7
A8: =A7+1 -> 7 | B8: {=INDEX('variable definitions Stephen2'!$1:$1,2+A8)} -> taxis | C8: Taxis | D8: =LEN(B8) -> 5
A9: =A8+1 -> 8 | B9: {=INDEX('variable definitions Stephen2'!$1:$1,2+A9)} -> pub_multi | C9: Multi-modal public | D9: =LEN(B9) -> 9
A10: =A9+1 -> 9 | B10: {=INDEX('variable definitions Stephen2'!$1:$1,2+A10)} -> pub_bus_coach | C10: Bus/coach | D10: =LEN(B10) -> 13
A11: =A10+1 -> 10 | B11: {=INDEX('variable definitions Stephen2'!$1:$1,2+A11)} -> pub_rail_tube | C11: Rail/tube | D11: =LEN(B11) -> 13
A12: =A11+1 -> 11 | B12: {=INDEX('variable definitions Stephen2'!$1:$1,2+A12)} -> pub_water | C12: Water | D12: =LEN(B12) -> 9
A13: =A12+1 -> 12 | B13: {=INDEX('variable definitions Stephen2'!$1:$1,2+A13)} -> motor1 | C13: Vehicle - cost of new car | van outright | D13: =LEN(B13) -> 6
A14: =A13+1 -> 13 | B14: {=INDEX('variable definitions Stephen2'!$1:$1,2+A14)} -> motor2 | C14: Vehicle - cost of 2nd hand car | van outright | D14: =LEN(B14) -> 6
... A23: =A22+1 -> 22 | B23: {=INDEX('variable definitions Stephen2'!$1:$1,2+A23)} -> motor_other | C23: Other vehicle costs | D23: =LEN(B23) -> 11

Sheet COICP transport
A1: variable | B1: description | C1: table | D1: coding_frame | E1: inUKDA | J1: ='variable definitions Stephen2'!A1 -> variable | K1: ='variable definitions Stephen2'!B1 -> description
A2: b216 | B2: Bus + tube and/or rail season | C2: dvhh | E2: Yes | F2: =MATCH(A2,'variable definitions Stephen2'!A:A) -> 2 | I2: =MATCH(J2,A:A,0) -> 2 | J2: ='variable definitions Stephen2'!A2 -> b216 | K2: ='variable definitions Stephen2'!B2 -> Bus + tube and/or rail season
A3: b217 | B3: Season ticket - bus / coach - total net amount | C3: dvhh | E3: Yes | F3: =MATCH(A3,'variable definitions Stephen2'!A:A) -> 3 | I3: =MATCH(J3,A:A,0) -> 3 | J3: ='variable definitions Stephen2'!A3 -> b217 | K3: ='variable definitions Stephen2'!B3 -> Season ticket - bus / coach - total net amount
A4: b218 | B4: Season ticket - rail / tube - total net amount | C4: dvhh | E4: Yes | F4: =MATCH(A4,'variable definitions Stephen2'!A:A) -> 4 | I4: =MATCH(J4,A:A,0) -> 4 | J4: ='variable definitions Stephen2'!A4 -> b218 | K4: ='variable definitions Stephen2'!B4 -> Season ticket - rail / tube - total net amount
A5: b219 | B5: Water travel season ticket | C5: dvhh | E5: Yes | F5: =MATCH(A5,'variable definitions Stephen2'!A:A) -> 5 | I5: =MATCH(J5,A:A,0) -> 5 | J5: ='variable definitions Stephen2'!A5 -> b219 | K5: ='variable definitions Stephen2'!B5 -> Water travel season ticket
A6: b244 | B6: Vehicle - cost of new car | van outright | C6: dvhh | E6: Yes | F6: =MATCH(A6,'variable definitions Stephen2'!A:A) -> 6 | I6: =MATCH(J6,A:A,0) -> 6 | J6: ='variable definitions Stephen2'!A6 -> b244 | K6: ='variable definitions Stephen2'!B6 -> Vehicle - cost of new car | van outright
A7: b245 | B7: Vehicle - cost of 2nd hand car | van outright | C7: dvhh | E7: Yes | F7: =MATCH(A7,'variable definitions Stephen2'!A:A) -> 8 | I7: =MATCH(J7,A:A,0) -> #N/A | J7: ='variable definitions Stephen2'!A7 -> b2441 | K7: ='variable definitions Stephen2'!B7 -> Vehicle - cost of new motor caravan outright
A8: b247 | B8: Vehicle - cost of motorcycles outright | C8: dvhh | E8: Yes | F8: =MATCH(A8,'variable definitions Stephen2'!A:A) -> 10 | I8: =MATCH(J8,A:A,0) -> 7 | J8: ='variable definitions Stephen2'!A8 -> b245 | K8: ='variable definitions Stephen2'!B8 -> Vehicle - cost of 2nd hand car | van outright
A9: b248 | B9: Car leasing - expenditure on | C9: dvhh | E9: Yes | F9: =MATCH(A9,'variable definitions Stephen2'!A:A) -> 11 | I9: =MATCH(J9,A:A,0) -> #N/A | J9: ='variable definitions Stephen2'!A9 -> b2451 | K9: ='variable definitions Stephen2'!B9 -> Vehicle cost of 2nd hand motor caravan outright
A10: b249 | B10: Car or van - servicing: amount paid | C10: dvhh | E10: Yes | F10: =MATCH(A10,'variable definitions Stephen2'!A:A) -> 12 | I10: =MATCH(J10,A:A,0) -> 8 | J10: ='variable definitions Stephen2'!A10 -> b247 | K10: ='variable definitions Stephen2'!B10 -> Vehicle - cost of motorcycles outright
A11: b250 | B11: Car or van - other works, repairs: amount paid | C11: dvhh | E11: Yes | F11: =MATCH(A11,'variable definitions Stephen2'!A:A) -> 13 | I11: =MATCH(J11,A:A,0) -> 9 | J11: ='variable definitions Stephen2'!A11 -> b248 | K11: ='variable definitions Stephen2'!B11 -> Car leasing - expenditure on
A12: b252 | B12: Motorcycle - services, repairs: amount paid | C12: dvhh | E12: Yes | F12: =MATCH(A12,'variable definitions Stephen2'!A:A) -> 14 | I12: =MATCH(J12,A:A,0) -> 10 | J12: ='variable definitions Stephen2'!A12 -> b249 | K12: ='variable definitions Stephen2'!B12 -> Car or van - servicing: amount paid
A13: b487 | B13: Domestic flight expenditure | C13: dvhh | E13: Yes | F13: =MATCH(A13,'variable definitions Stephen2'!A:A) -> 15 | I13: =MATCH(J13,A:A,0) -> 11 | J13: ='variable definitions Stephen2'!A13 -> b250 | K13: ='variable definitions Stephen2'!B13 -> Car or van - other works, repairs: amount paid
... A46: c73611t | B46: Delivery charges and other transport services | C46: dvhh | E46: Yes | F46: =MATCH(A46,'variable definitions Stephen2'!A:A) -> 48 | I46: =MATCH(J46,A:A,0) -> 44 | J46: ='variable definitions Stephen2'!A46 -> c73512t | K46: ='variable definitions Stephen2'!B46 -> Combined fares other than season tickets
I47: =MATCH(J47,A:A,0) -> 45 | J47: ='variable definitions Stephen2'!A47 -> c73513t | K47: ='variable definitions Stephen2'!B47 -> School travel
I48: =MATCH(J48,A:A,0) -> 46 | J48: ='variable definitions Stephen2'!A48 -> c73611t | K48: ='variable definitions Stephen2'!B48 -> Delivery charges and other transport services
I49: =MATCH(J49,A:A,0) -> #N/A | J49: ='variable definitions Stephen2'!A49 -> b187 | K49: ='variable definitions Stephen2'!B49 -> Vehicle road tax - amount paid last year
I50: =MATCH(J50,A:A,0) -> #N/A | J50: ='variable definitions Stephen2'!A50 -> b179 | K50: ='variable definitions Stephen2'!B50 -> Vehicle road tax - amount refunded last
I51: =MATCH(J51,A:A,0) -> #N/A | J51: ='variable definitions Stephen2'!A51 -> ck3112t | K51: ='variable definitions Stephen2'!B51 -> Motoring Fines
I52: =MATCH(J52,A:A,0) -> #N/A | J52: ='variable definitions Stephen2'!A52 -> b188 | K52: ='variable definitions Stephen2'!B52 -> Vehicle insurance - amount paid last yea
I53: =MATCH(J53,A:A,0) -> #N/A | J53: ='variable definitions Stephen2'!A53 -> c92114t | K53: ='variable definitions Stephen2'!B53 -> Purchase of motor caravan (new) - loan/HP

Sheet Sheet1
A1: variable | B1: description | C1: table | D1: coding_frame | E1: inUKDA | F1: pub_priv | G1: active | H1: taxi | I1: surface | J1: Notes
A2: c73611 | B2: Delivery charges and other transport services | C2: dvhh | E2: Yes | F2: private | G2: motor | H2: not_taxi | I2: surface | J2: Not sure about this one - possibly ignore as we focus largely on personal travel?
A4: Air travel
A5: c73311 | B5: Air fares (within UK) | C5: dvhh | E5: Yes | F5: public | G5: motor | H5: not_taxi | I5: air
A6: c73312 | B6: Air fares (international) | C6: dvhh | E6: Yes | F6: public | G6: motor | H6: not_taxi | I6: air
A8: Public transport, cycling and other costs
A9: Public transport
A10: b216 | B10: Bus + tube and/or rail season | C10: dvhh | E10: Yes | F10: public | G10: motor | H10: not_taxi | I10: surface
A11: b217 | B11: Season ticket - bus / coach - total net amount | C11: dvhh | E11: Yes | F11: public | G11: motor | H11: not_taxi | I11: surface
A12: b218 | B12: Season ticket - rail / tube - total net amount | C12: dvhh | E12: Yes | F12: public | G12: motor | H12: not_taxi | I12: surface
A13: c73411 | B13: Water travel | C13: dvhh | E13: Yes | F13: public | G13: motor | H13: not_taxi | I13: surface
A14: c73512 | B14: Combined fares other than season tickets | C14: dvhh | E14: Yes | F14: public | G14: motor | H14: not_taxi | I14: surface
A15: c73112 | B15: Railway and tube fares other than season tickets | C15: dvhh | E15: Yes | F15: public | G15: motor | H15: not_taxi | I15: surface
A16: c73212 | B16: Bus and coach fares other than season tickets | C16: dvhh | E16: Yes | F16: public | G16: motor | H16: not_taxi | I16: surface
A17: b219 | B17: Water travel season ticket | C17: dvhh | E17: Yes | F17: public | G17: motor | H17: not_taxi | I17: surface
A18: Cycling
A19: c71311 | B19: Purchase of bicycle | C19: dvhh | E19: Yes | F19: private | G19: active | H19: not_taxi | I19: surface
A20: c72115 | B20: Bicycle accessories, repairs and other costs | C20: dvhh | E20: Yes | F20: private | G20: active | H20: not_taxi | I20: surface
A21: Other
A22: c73513 | B22: School travel | C22: dvhh | E22: Yes | F22: public | G22: motor | H22: not_taxi | I22: surface
A23: c73214 | B23: Other personal travel | C23: dvhh | E23: Yes | F23: private | G23: other | H23: not_taxi | I23: surface
A24: c71411 | B24: Animal drawn vehicles | C24: dvhh | E24: Yes | F24: private | G24: other | H24: not_taxi | I24: surface
A25: c72414 | B25: Hire of self-drive cars, vans, bicycles | C25: dvhh | E25: Yes | F25: private | G25: motor | H25: not_taxi | I25: surface
A27: Taxis and minicabs
A28: c73213 | B28: Taxis and hired cars with drivers | C28: dvhh | E28: Yes | F28: private | G28: motor | H28: taxi | I28: surface
A30: Motoring
A31: Purchase or leasing of vehicles
A32: b244 | B32: Vehicle - cost of new car | van outright | C32: dvhh | E32: Yes | F32: private | G32: motor | H32: not_taxi | I32: surface
A33: b245 | B33: Vehicle - cost of 2nd hand car | van outright | C33: dvhh | E33: Yes | F33: private | G33: motor | H33: not_taxi | I33: surface
A34: b247 | B34: Vehicle - cost of motorcycles outright | C34: dvhh | E34: Yes | F34: private | G34: motor | H34: not_taxi | I34: surface
A35: c71112 | B35: Loan / HP purchase of new car/van | C35: dvhh | E35: Yes | F35: private | G35: motor | H35: not_taxi | I35: surface
A36: c71122 | B36: Loan / HP purchase of second-hand car/van | C36: dvhh | E36: Yes | F36: private | G36: motor | H36: not_taxi | I36: surface
A37: c71212 | B37: Loan / HP purchase of new or second-hand motorcycle | C37: dvhh | E37: Yes | F37: private | G37: motor | H37: not_taxi | I37: surface
B38: Motor vehicle road taxation payments less refunds | J38: THIS VARIABLE IS NOT AVAILABLE IN THE EUL VERSION - USING TWO VARIABLES ABOUT LAST YEAR
A39: b248 | B39: Car leasing - expenditure on | C39: dvhh | E39: Yes | F39: private | G39: motor | H39: not_taxi | I39: surface
A40: Operation of private vehicles
A41: c72111 | B41: Car van accessories and fittings | C41: dvhh | E41: Yes | F41: private | G41: motor | H41: not_taxi | I41: surface
A42: c72112 | B42: Car / van spare parts | C42: dvhh | E42: Yes | F42: private | G42: motor | H42: not_taxi | I42: surface
A43: c72113 | B43: Motorcycle accessories and spare parts | C43: dvhh | E43: Yes | F43: private | G43: motor | H43: not_taxi | I43: surface
A44: c72211 | B44: Petrol | C44: dvhh | E44: Yes | F44: private | G44: motor | H44: not_taxi | I44: surface
...

Sheet Motoring expenditure RPI
A2: P133 | B2: Motoring expenditure - RPI definition, expenditure by adults only:‑ | F2: adult in existing list | G2: total in existing list
A3: variable | B3: description | C3: table | D3: coding_frame | E3: inUKDA
A4: c31315 | B4: Protective head gear (crash helmets) | C4: dvhh | E4: Yes | F4: =MATCH(A4,'variable definitions Stephen'!A:A,0) -> #N/A | G4: =MATCH(A4&"t",'variable definitions Stephen'!A:A,0) -> #N/A
A5: c71112 | B5: Loan / HP purchase of new car/van | C5: dvhh | E5: Yes | F5: =MATCH(A5,'variable definitions Stephen'!A:A,0) -> #N/A | G5: =MATCH(A5&"t",'variable definitions Stephen'!A:A,0) -> 18
A6: c71122 | B6: Loan / HP purchase of second-hand car/van | C6: dvhh | E6: Yes | F6: =MATCH(A6,'variable definitions Stephen'!A:A,0) -> #N/A | G6: =MATCH(A6&"t",'variable definitions Stephen'!A:A,0) -> 20
A7: c71212 | B7: Loan / HP purchase of new or second-hand motorcycle | C7: dvhh | E7: Yes | F7: =MATCH(A7,'variable definitions Stephen'!A:A,0) -> #N/A | G7: =MATCH(A7&"t",'variable definitions Stephen'!A:A,0) -> 22
A8: c72111 | B8: Car van accessories and fittings | C8: dvhh | E8: Yes | F8: =MATCH(A8,'variable definitions Stephen'!A:A,0) -> #N/A | G8: =MATCH(A8&"t",'variable definitions Stephen'!A:A,0) -> 25
A9: c72112 | B9: Car / van spare parts | C9: dvhh | E9: Yes | F9: =MATCH(A9,'variable definitions Stephen'!A:A,0) -> #N/A | G9: =MATCH(A9&"t",'variable definitions Stephen'!A:A,0) -> 26
A10: c72113 | B10: Motorcycle accessories and spare parts | C10: dvhh | E10: Yes | F10: =MATCH(A10,'variable definitions Stephen'!A:A,0) -> #N/A | G10: =MATCH(A10&"t",'variable definitions Stephen'!A:A,0) -> 27
A11: c72114 | B11: Anti-freeze, battery water, cleaning materials | C11: dvhh | E11: Yes | F11: =MATCH(A11,'variable definitions Stephen'!A:A,0) -> #N/A | G11: =MATCH(A11&"t",'variable definitions Stephen'!A:A,0) -> 28
A12: c72211 | B12: Petrol | C12: dvhh | E12: Yes | F12: =MATCH(A12,'variable definitions Stephen'!A:A,0) -> #N/A | G12: =MATCH(A12&"t",'variable definitions Stephen'!A:A,0) -> 30
A13: c72212 | B13: Diesel oil | C13: dvhh | E13: Yes | F13: =MATCH(A13,'variable definitions Stephen'!A:A,0) -> #N/A | G13: =MATCH(A13&"t",'variable definitions Stephen'!A:A,0) -> 31
A14: c72213 | B14: Other motor oils | C14: dvhh | E14: Yes | F14: =MATCH(A14,'variable definitions Stephen'!A:A,0) -> #N/A | G14: =MATCH(A14&"t",'variable definitions Stephen'!A:A,0) -> 32
A15: c72313 | B15: Motoring organisation subscription (eg AA and RAC) | C15: dvhh | E15: Yes | F15: =MATCH(A15,'variable definitions Stephen'!A:A,0) -> #N/A | G15: =MATCH(A15&"t",'variable definitions Stephen'!A:A,0) -> 35
... A22: c92116 | B22: Purchase of motor caravan (second-hand) - loan/HP | C22: dvhh | E22: Yes | F22: =MATCH(A22,'variable definitions Stephen'!A:A,0) -> #N/A | G22: =MATCH(A22&"t",'variable definitions Stephen'!A:A,0) -> #N/A
A24: P133c | B24: Motoring expenditure - RPI definition, expenditure by children only:‑ | F24: child amount in existing list | G24: in existing list | H24: in list above
A25: variable | B25: description | C25: table | D25: coding_frame | E25: inUKDA
A26: c31315c | B26: Protective head gear (crash helmets) | C26: dvhh | E26: Yes | F26: =MATCH(A26,'variable definitions Stephen'!A:A,0) -> #N/A | G26: =MATCH(LEFT(A26,6)&"t",'variable definitions Stephen'!A:A,0) -> #N/A | H26: =MATCH(B26,$B$4:$B$22,0) -> 1
A27: c71111c | B27: Outright purchase of new car/van | C27: dvhh | E27: Yes | F27: =MATCH(A27,'variable definitions Stephen'!A:A,0) -> 17 | G27: =MATCH(LEFT(A27,6)&"t",'variable definitions Stephen'!A:A,0) -> #N/A | H27: =MATCH(B27,$B$4:$B$22,0) -> #N/A
A28: c71121c | B28: Outright purchase of second-hand car/van | C28: dvhh | E28: Yes | F28: =MATCH(A28,'variable definitions Stephen'!A:A,0) -> 19 | G28: =MATCH(LEFT(A28,6)&"t",'variable definitions Stephen'!A:A,0) -> #N/A | H28: =MATCH(B28,$B$4:$B$22,0) -> #N/A
A29: c71211c | B29: Outright purchase of new or second-hand motorcycle | C29: dvhh | E29: Yes | F29: =MATCH(A29,'variable definitions Stephen'!A:A,0) -> 21 | G29: =MATCH(LEFT(A29,6)&"t",'variable definitions Stephen'!A:A,0) -> #N/A | H29: =MATCH(B29,$B$4:$B$22,0) -> #N/A
A30: c72111c | B30: Car van accessories and fittings | C30: dvhh | E30: Yes | F30: =MATCH(A30,'variable definitions Stephen'!A:A,0) -> #N/A | G30: =MATCH(LEFT(A30,6)&"t",'variable definitions Stephen'!A:A,0) -> 25 | H30: =MATCH(B30,$B$4:$B$22,0) -> 5
A31: c72113c | B31: Motorcycle accessories and spare parts | C31: dvhh | E31: Yes | F31: =MATCH(A31,'variable definitions Stephen'!A:A,0) -> #N/A | G31: =MATCH(LEFT(A31,6)&"t",'variable definitions Stephen'!A:A,0) -> 27 | H31: =MATCH(B31,$B$4:$B$22,0) -> 7
A32: c72114c | B32: Anti-freeze, battery water, cleaning materials | C32: dvhh | E32: Yes | F32: =MATCH(A32,'variable definitions Stephen'!A:A,0) -> #N/A | G32: =MATCH(LEFT(A32,6)&"t",'variable definitions Stephen'!A:A,0) -> 28 | H32: =MATCH(B32,$B$4:$B$22,0) -> 8
A33: c72211c | B33: Petrol | C33: dvhh | E33: Yes | F33: =MATCH(A33,'variable definitions Stephen'!A:A,0) -> #N/A | G33: =MATCH(LEFT(A33,6)&"t",'variable definitions Stephen'!A:A,0) -> 30 | H33: =MATCH(B33,$B$4:$B$22,0) -> 9
A34: c72212c | B34: Diesel oil | C34: dvhh | E34: Yes | F34: =MATCH(A34,'variable definitions Stephen'!A:A,0) -> #N/A | G34: =MATCH(LEFT(A34,6)&"t",'variable definitions Stephen'!A:A,0) -> 31 | H34: =MATCH(B34,$B$4:$B$22,0) -> 10
A35: c72213c | B35: Other motor oils | C35: dvhh | E35: Yes | F35: =MATCH(A35,'variable definitions Stephen'!A:A,0) -> #N/A | G35: =MATCH(LEFT(A35,6)&"t",'variable definitions Stephen'!A:A,0) -> 32 | H35: =MATCH(B35,$B$4:$B$22,0) -> 11
A36: c72311c | B36: Car or van repairs and servicing | C36: dvhh | E36: Yes | F36: =MATCH(A36,'variable definitions Stephen'!A:A,0) -> 33 | G36: =MATCH(LEFT(A36,6)&"t",'variable definitions Stephen'!A:A,0) -> #N/A | H36: =MATCH(B36,$B$4:$B$22,0) -> #N/A
A37: c72312c | B37: Motor cycle repairs, service | C37: dvhh | E37: Yes | F37: =MATCH(A37,'variable definitions Stephen'!A:A,0) -> 34 | G37: =MATCH(LEFT(A37,6)&"t",'variable definitions Stephen'!A:A,0) -> #N/A | H37: =MATCH(B37,$B$4:$B$22,0) -> #N/A
... A45: c92115c | B45: Purchase of motor caravan (second-hand) - outright purchase | C45: dvhh | E45: Yes | F45: =MATCH(A45,'variable definitions Stephen'!A:A,0) -> #N/A | G45: =MATCH(LEFT(A45,6)&"t",'variable definitions Stephen'!A:A,0) -> #N/A | H45: =MATCH(B45,$B$4:$B$22,0) -> #N/A

Sheet fares expenditure total
A3: variable | B3: description | C3: table | D3: coding_frame | E3: inUKDA
A4: c71311t | B4: Purchase of bicycle | C4: dvhh | E4: Yes | F4: =MATCH(A4,'variable definitions Stephen'!A:A,0) -> 23
A5: c71411t | B5: Animal drawn vehicles | C5: dvhh | E5: Yes | F5: =MATCH(A5,'variable definitions Stephen'!A:A,0) -> 24
A6: c72115t | B6: Bicycle accessories, repairs and other costs | C6: dvhh | E6: Yes | F6: =MATCH(A6,'variable definitions Stephen'!A:A,0) -> 29
A7: c72414t | B7: Hire of self-drive cars, vans, bicycles | C7: dvhh | E7: Yes | F7: =MATCH(A7,'variable definitions Stephen'!A:A,0) -> 40
A8: c73112t | B8: Bus and coach fares other than season tickets | C8: dvhh | E8: Yes | F8: =MATCH(A8,'variable definitions Stephen'!A:A,0) -> 41
A9: c73212t | B9: Bus and coach fares other than season tickets | C9: dvhh | E9: Yes | F9: =MATCH(A9,'variable definitions Stephen'!A:A,0) -> 42
A10: c73213t | B10: Taxis and hired cars with drivers | C10: dvhh | E10: Yes | F10: =MATCH(A10,'variable definitions Stephen'!A:A,0) -> 43
A11: c73214t | B11: Other personal travel | C11: dvhh | E11: Yes | F11: =MATCH(A11,'variable definitions Stephen'!A:A,0) -> 44
A12: c73311t | B12: Air fares (within UK) | C12: dvhh | E12: Yes | F12: =MATCH(A12,'variable definitions Stephen'!A:A,0) -> #N/A
A13: c73312t | B13: Air fares (international) | C13: dvhh | E13: Yes | F13: =MATCH(A13,'variable definitions Stephen'!A:A,0) -> #N/A
A14: c73411t | B14: Water travel | C14: dvhh | E14: Yes | F14: =MATCH(A14,'variable definitions Stephen'!A:A,0) -> 45
A15: c73512t | B15: Combined fares other than season tickets | C15: dvhh | E15: Yes | F15: =MATCH(A15,'variable definitions Stephen'!A:A,0) -> 46
... A20: c92311t | B20: Maintenance & repair of other durables for recreation & culture | C20: dvhh | E20: Yes | F20: =MATCH(A20,'variable definitions Stephen'!A:A,0) -> #N/A

Sheet codes starting 73
A2: c71111c | B2: Outright purchase of new car/van | C2: =MATCH(A2,'variable definitions Stephen'!A:A,0) -> 17
A3: c71111w | B3: Outright purchase of new car/van | C3: =MATCH(A3,'variable definitions Stephen'!A:A,0) -> #N/A
A4: c71112 | B4: Loan / HP purchase of new car/van | C4: =MATCH(A4,'variable definitions Stephen'!A:A,0) -> #N/A
A5: c71112t | B5: Loan / HP purchase of new car/van | C5: =MATCH(A5,'variable definitions Stephen'!A:A,0) -> 18
A6: c71121c | B6: Outright purchase of second-hand car/van | C6: =MATCH(A6,'variable definitions Stephen'!A:A,0) -> 19
A7: c71122 | B7: Loan / HP purchase of second-hand car/van | C7: =MATCH(A7,'variable definitions Stephen'!A:A,0) -> #N/A
A8: c71122t | B8: Loan / HP purchase of second-hand car/van | C8: =MATCH(A8,'variable definitions Stephen'!A:A,0) -> 20
A9: c71211c | B9: Outright purchase of new or second-hand motorcycle | C9: =MATCH(A9,'variable definitions Stephen'!A:A,0) -> 21
A10: c71211w | B10: Outright purchase of new or second-hand motorcycle | C10: =MATCH(A10,'variable definitions Stephen'!A:A,0) -> #N/A
A11: c71212 | B11: Loan / HP purchase of new or second-hand motorcycle | C11: =MATCH(A11,'variable definitions Stephen'!A:A,0) -> #N/A
A12: c71212t | B12: Loan / HP purchase of new or second-hand motorcycle | C12: =MATCH(A12,'variable definitions Stephen'!A:A,0) -> 22
A13: c71311 | B13: Purchase of bicycle | C13: =MATCH(A13,'variable definitions Stephen'!A:A,0) -> #N/A
... A107: c73611t | B107: Delivery charges and other transport services | C107: =MATCH(A107,'variable definitions Stephen'!A:A,0) -> 48
